[2015-06-19 11:41:26 +0000] [4358] [INFO] Starting gunicorn 19.3.0
[2015-06-19 11:41:26 +0000] [4358] [INFO] Listening at: http://0.0.0.0:80 (4358)
[2015-06-19 11:41:26 +0000] [4358] [INFO] Using worker: sync
[2015-06-19 11:41:26 +0000] [4358] [INFO] Server is ready. Spawning workers
[2015-06-19 11:41:26 +0000] [4363] [INFO] Booting worker with pid: 4363
[2015-06-19 11:41:26 +0000] [4363] [INFO] Worker spawned (pid: 4363)
[2015-06-19 11:41:56 +0000] [4363] [ERROR] Error handling request
Traceback (most recent call last):
  File "/usr/local/lib/python2.7/dist-packages/gunicorn/workers/sync.py", line 130, in handle
    self.handle_request(listener, req, client, addr)
  File "/usr/local/lib/python2.7/dist-packages/gunicorn/workers/sync.py", line 171, in handle_request
    respiter = self.wsgi(environ, resp.start_response)
  File "/usr/local/lib/python2.7/dist-packages/flask/app.py", line 1836, in __call__
    return self.wsgi_app(environ, start_response)
  File "/usr/local/lib/python2.7/dist-packages/werkzeug/contrib/fixers.py", line 148, in __call__
    return self.app(environ, start_response)
  File "/usr/local/lib/python2.7/dist-packages/flask/app.py", line 1820, in wsgi_app
    response = self.make_response(self.handle_exception(e))
  File "/usr/local/lib/python2.7/dist-packages/flask/app.py", line 1403, in handle_exception
    reraise(exc_type, exc_value, tb)
  File "/usr/local/lib/python2.7/dist-packages/flask/app.py", line 1817, in wsgi_app
    response = self.full_dispatch_request()
  File "/usr/local/lib/python2.7/dist-packages/flask/app.py", line 1477, in full_dispatch_request
    rv = self.handle_user_exception(e)
  File "/usr/local/lib/python2.7/dist-packages/flask/app.py", line 1370, in handle_user_exception
    return self.handle_http_exception(e)
  File "/usr/local/lib/python2.7/dist-packages/flask/app.py", line 1330, in handle_http_exception
    return handler(e)
  File "/home/pi/Feedback_box/FeedBack_Box/FeedBack_Box.py", line 144, in page_not_found
    print(request.url)
UnicodeEncodeError: 'ascii' codec can't encode characters in position 110-111: ordinal not in range(128)
[2015-06-19 11:41:57 +0000] [4363] [ERROR] Error handling request
Traceback (most recent call last):
  File "/usr/local/lib/python2.7/dist-packages/gunicorn/workers/sync.py", line 130, in handle
    self.handle_request(listener, req, client, addr)
  File "/usr/local/lib/python2.7/dist-packages/gunicorn/workers/sync.py", line 171, in handle_request
    respiter = self.wsgi(environ, resp.start_response)
  File "/usr/local/lib/python2.7/dist-packages/flask/app.py", line 1836, in __call__
    return self.wsgi_app(environ, start_response)
  File "/usr/local/lib/python2.7/dist-packages/werkzeug/contrib/fixers.py", line 148, in __call__
    return self.app(environ, start_response)
  File "/usr/local/lib/python2.7/dist-packages/flask/app.py", line 1820, in wsgi_app
    response = self.make_response(self.handle_exception(e))
  File "/usr/local/lib/python2.7/dist-packages/flask/app.py", line 1403, in handle_exception
    reraise(exc_type, exc_value, tb)
  File "/usr/local/lib/python2.7/dist-packages/flask/app.py", line 1817, in wsgi_app
    response = self.full_dispatch_request()
  File "/usr/local/lib/python2.7/dist-packages/flask/app.py", line 1477, in full_dispatch_request
    rv = self.handle_user_exception(e)
  File "/usr/local/lib/python2.7/dist-packages/flask/app.py", line 1370, in handle_user_exception
    return self.handle_http_exception(e)
  File "/usr/local/lib/python2.7/dist-packages/flask/app.py", line 1330, in handle_http_exception
    return handler(e)
  File "/home/pi/Feedback_box/FeedBack_Box/FeedBack_Box.py", line 144, in page_not_found
    print(request.url)
UnicodeEncodeError: 'ascii' codec can't encode character u'\xe9' in position 537: ordinal not in range(128)
[2015-06-19 11:41:57 +0000] [4363] [ERROR] Error handling request
Traceback (most recent call last):
  File "/usr/local/lib/python2.7/dist-packages/gunicorn/workers/sync.py", line 130, in handle
    self.handle_request(listener, req, client, addr)
  File "/usr/local/lib/python2.7/dist-packages/gunicorn/workers/sync.py", line 171, in handle_request
    respiter = self.wsgi(environ, resp.start_response)
  File "/usr/local/lib/python2.7/dist-packages/flask/app.py", line 1836, in __call__
    return self.wsgi_app(environ, start_response)
  File "/usr/local/lib/python2.7/dist-packages/werkzeug/contrib/fixers.py", line 148, in __call__
    return self.app(environ, start_response)
  File "/usr/local/lib/python2.7/dist-packages/flask/app.py", line 1820, in wsgi_app
    response = self.make_response(self.handle_exception(e))
  File "/usr/local/lib/python2.7/dist-packages/flask/app.py", line 1403, in handle_exception
    reraise(exc_type, exc_value, tb)
  File "/usr/local/lib/python2.7/dist-packages/flask/app.py", line 1817, in wsgi_app
    response = self.full_dispatch_request()
  File "/usr/local/lib/python2.7/dist-packages/flask/app.py", line 1477, in full_dispatch_request
    rv = self.handle_user_exception(e)
  File "/usr/local/lib/python2.7/dist-packages/flask/app.py", line 1370, in handle_user_exception
    return self.handle_http_exception(e)
  File "/usr/local/lib/python2.7/dist-packages/flask/app.py", line 1330, in handle_http_exception
    return handler(e)
  File "/home/pi/Feedback_box/FeedBack_Box/FeedBack_Box.py", line 144, in page_not_found
    print(request.url)
UnicodeEncodeError: 'ascii' codec can't encode character u'\xe9' in position 537: ordinal not in range(128)
[2015-06-19 11:42:04 +0000] [4363] [ERROR] Error handling request
Traceback (most recent call last):
  File "/usr/local/lib/python2.7/dist-packages/gunicorn/workers/sync.py", line 130, in handle
    self.handle_request(listener, req, client, addr)
  File "/usr/local/lib/python2.7/dist-packages/gunicorn/workers/sync.py", line 171, in handle_request
    respiter = self.wsgi(environ, resp.start_response)
  File "/usr/local/lib/python2.7/dist-packages/flask/app.py", line 1836, in __call__
    return self.wsgi_app(environ, start_response)
  File "/usr/local/lib/python2.7/dist-packages/werkzeug/contrib/fixers.py", line 148, in __call__
    return self.app(environ, start_response)
  File "/usr/local/lib/python2.7/dist-packages/flask/app.py", line 1820, in wsgi_app
    response = self.make_response(self.handle_exception(e))
  File "/usr/local/lib/python2.7/dist-packages/flask/app.py", line 1403, in handle_exception
    reraise(exc_type, exc_value, tb)
  File "/usr/local/lib/python2.7/dist-packages/flask/app.py", line 1817, in wsgi_app
    response = self.full_dispatch_request()
  File "/usr/local/lib/python2.7/dist-packages/flask/app.py", line 1477, in full_dispatch_request
    rv = self.handle_user_exception(e)
  File "/usr/local/lib/python2.7/dist-packages/flask/app.py", line 1370, in handle_user_exception
    return self.handle_http_exception(e)
  File "/usr/local/lib/python2.7/dist-packages/flask/app.py", line 1330, in handle_http_exception
    return handler(e)
  File "/home/pi/Feedback_box/FeedBack_Box/FeedBack_Box.py", line 144, in page_not_found
    print(request.url)
UnicodeEncodeError: 'ascii' codec can't encode characters in position 110-111: ordinal not in range(128)
[2015-06-19 11:42:04 +0000] [4363] [ERROR] Error handling request
Traceback (most recent call last):
  File "/usr/local/lib/python2.7/dist-packages/gunicorn/workers/sync.py", line 130, in handle
    self.handle_request(listener, req, client, addr)
  File "/usr/local/lib/python2.7/dist-packages/gunicorn/workers/sync.py", line 171, in handle_request
    respiter = self.wsgi(environ, resp.start_response)
  File "/usr/local/lib/python2.7/dist-packages/flask/app.py", line 1836, in __call__
    return self.wsgi_app(environ, start_response)
  File "/usr/local/lib/python2.7/dist-packages/werkzeug/contrib/fixers.py", line 148, in __call__
    return self.app(environ, start_response)
  File "/usr/local/lib/python2.7/dist-packages/flask/app.py", line 1820, in wsgi_app
    response = self.make_response(self.handle_exception(e))
  File "/usr/local/lib/python2.7/dist-packages/flask/app.py", line 1403, in handle_exception
    reraise(exc_type, exc_value, tb)
  File "/usr/local/lib/python2.7/dist-packages/flask/app.py", line 1817, in wsgi_app
    response = self.full_dispatch_request()
  File "/usr/local/lib/python2.7/dist-packages/flask/app.py", line 1477, in full_dispatch_request
    rv = self.handle_user_exception(e)
  File "/usr/local/lib/python2.7/dist-packages/flask/app.py", line 1370, in handle_user_exception
    return self.handle_http_exception(e)
  File "/usr/local/lib/python2.7/dist-packages/flask/app.py", line 1330, in handle_http_exception
    return handler(e)
  File "/home/pi/Feedback_box/FeedBack_Box/FeedBack_Box.py", line 144, in page_not_found
    print(request.url)
UnicodeEncodeError: 'ascii' codec can't encode character u'\xe9' in position 537: ordinal not in range(128)
[2015-06-19 11:42:04 +0000] [4363] [ERROR] Error handling request
Traceback (most recent call last):
  File "/usr/local/lib/python2.7/dist-packages/gunicorn/workers/sync.py", line 130, in handle
    self.handle_request(listener, req, client, addr)
  File "/usr/local/lib/python2.7/dist-packages/gunicorn/workers/sync.py", line 171, in handle_request
    respiter = self.wsgi(environ, resp.start_response)
  File "/usr/local/lib/python2.7/dist-packages/flask/app.py", line 1836, in __call__
    return self.wsgi_app(environ, start_response)
  File "/usr/local/lib/python2.7/dist-packages/werkzeug/contrib/fixers.py", line 148, in __call__
    return self.app(environ, start_response)
  File "/usr/local/lib/python2.7/dist-packages/flask/app.py", line 1820, in wsgi_app
    response = self.make_response(self.handle_exception(e))
  File "/usr/local/lib/python2.7/dist-packages/flask/app.py", line 1403, in handle_exception
    reraise(exc_type, exc_value, tb)
  File "/usr/local/lib/python2.7/dist-packages/flask/app.py", line 1817, in wsgi_app
    response = self.full_dispatch_request()
  File "/usr/local/lib/python2.7/dist-packages/flask/app.py", line 1477, in full_dispatch_request
    rv = self.handle_user_exception(e)
  File "/usr/local/lib/python2.7/dist-packages/flask/app.py", line 1370, in handle_user_exception
    return self.handle_http_exception(e)
  File "/usr/local/lib/python2.7/dist-packages/flask/app.py", line 1330, in handle_http_exception
    return handler(e)
  File "/home/pi/Feedback_box/FeedBack_Box/FeedBack_Box.py", line 144, in page_not_found
    print(request.url)
UnicodeEncodeError: 'ascii' codec can't encode character u'\xe9' in position 537: ordinal not in range(128)
[2015-06-19 11:42:09 +0000] [4363] [ERROR] Error handling request
Traceback (most recent call last):
  File "/usr/local/lib/python2.7/dist-packages/gunicorn/workers/sync.py", line 130, in handle
    self.handle_request(listener, req, client, addr)
  File "/usr/local/lib/python2.7/dist-packages/gunicorn/workers/sync.py", line 171, in handle_request
    respiter = self.wsgi(environ, resp.start_response)
  File "/usr/local/lib/python2.7/dist-packages/flask/app.py", line 1836, in __call__
    return self.wsgi_app(environ, start_response)
  File "/usr/local/lib/python2.7/dist-packages/werkzeug/contrib/fixers.py", line 148, in __call__
    return self.app(environ, start_response)
  File "/usr/local/lib/python2.7/dist-packages/flask/app.py", line 1820, in wsgi_app
    response = self.make_response(self.handle_exception(e))
  File "/usr/local/lib/python2.7/dist-packages/flask/app.py", line 1403, in handle_exception
    reraise(exc_type, exc_value, tb)
  File "/usr/local/lib/python2.7/dist-packages/flask/app.py", line 1817, in wsgi_app
    response = self.full_dispatch_request()
  File "/usr/local/lib/python2.7/dist-packages/flask/app.py", line 1477, in full_dispatch_request
    rv = self.handle_user_exception(e)
  File "/usr/local/lib/python2.7/dist-packages/flask/app.py", line 1370, in handle_user_exception
    return self.handle_http_exception(e)
  File "/usr/local/lib/python2.7/dist-packages/flask/app.py", line 1330, in handle_http_exception
    return handler(e)
  File "/home/pi/Feedback_box/FeedBack_Box/FeedBack_Box.py", line 144, in page_not_found
    print(request.url)
UnicodeEncodeError: 'ascii' codec can't encode characters in position 110-111: ordinal not in range(128)
[2015-06-19 11:42:10 +0000] [4363] [ERROR] Error handling request
Traceback (most recent call last):
  File "/usr/local/lib/python2.7/dist-packages/gunicorn/workers/sync.py", line 130, in handle
    self.handle_request(listener, req, client, addr)
  File "/usr/local/lib/python2.7/dist-packages/gunicorn/workers/sync.py", line 171, in handle_request
    respiter = self.wsgi(environ, resp.start_response)
  File "/usr/local/lib/python2.7/dist-packages/flask/app.py", line 1836, in __call__
    return self.wsgi_app(environ, start_response)
  File "/usr/local/lib/python2.7/dist-packages/werkzeug/contrib/fixers.py", line 148, in __call__
    return self.app(environ, start_response)
  File "/usr/local/lib/python2.7/dist-packages/flask/app.py", line 1820, in wsgi_app
    response = self.make_response(self.handle_exception(e))
  File "/usr/local/lib/python2.7/dist-packages/flask/app.py", line 1403, in handle_exception
    reraise(exc_type, exc_value, tb)
  File "/usr/local/lib/python2.7/dist-packages/flask/app.py", line 1817, in wsgi_app
    response = self.full_dispatch_request()
  File "/usr/local/lib/python2.7/dist-packages/flask/app.py", line 1477, in full_dispatch_request
    rv = self.handle_user_exception(e)
  File "/usr/local/lib/python2.7/dist-packages/flask/app.py", line 1370, in handle_user_exception
    return self.handle_http_exception(e)
  File "/usr/local/lib/python2.7/dist-packages/flask/app.py", line 1330, in handle_http_exception
    return handler(e)
  File "/home/pi/Feedback_box/FeedBack_Box/FeedBack_Box.py", line 144, in page_not_found
    print(request.url)
UnicodeEncodeError: 'ascii' codec can't encode character u'\xe9' in position 537: ordinal not in range(128)
[2015-06-19 11:42:10 +0000] [4363] [ERROR] Error handling request
Traceback (most recent call last):
  File "/usr/local/lib/python2.7/dist-packages/gunicorn/workers/sync.py", line 130, in handle
    self.handle_request(listener, req, client, addr)
  File "/usr/local/lib/python2.7/dist-packages/gunicorn/workers/sync.py", line 171, in handle_request
    respiter = self.wsgi(environ, resp.start_response)
  File "/usr/local/lib/python2.7/dist-packages/flask/app.py", line 1836, in __call__
    return self.wsgi_app(environ, start_response)
  File "/usr/local/lib/python2.7/dist-packages/werkzeug/contrib/fixers.py", line 148, in __call__
    return self.app(environ, start_response)
  File "/usr/local/lib/python2.7/dist-packages/flask/app.py", line 1820, in wsgi_app
    response = self.make_response(self.handle_exception(e))
  File "/usr/local/lib/python2.7/dist-packages/flask/app.py", line 1403, in handle_exception
    reraise(exc_type, exc_value, tb)
  File "/usr/local/lib/python2.7/dist-packages/flask/app.py", line 1817, in wsgi_app
    response = self.full_dispatch_request()
  File "/usr/local/lib/python2.7/dist-packages/flask/app.py", line 1477, in full_dispatch_request
    rv = self.handle_user_exception(e)
  File "/usr/local/lib/python2.7/dist-packages/flask/app.py", line 1370, in handle_user_exception
    return self.handle_http_exception(e)
  File "/usr/local/lib/python2.7/dist-packages/flask/app.py", line 1330, in handle_http_exception
    return handler(e)
  File "/home/pi/Feedback_box/FeedBack_Box/FeedBack_Box.py", line 144, in page_not_found
    print(request.url)
UnicodeEncodeError: 'ascii' codec can't encode character u'\xe9' in position 537: ordinal not in range(128)
[2015-06-19 11:42:14 +0000] [4363] [ERROR] Error handling request
Traceback (most recent call last):
  File "/usr/local/lib/python2.7/dist-packages/gunicorn/workers/sync.py", line 130, in handle
    self.handle_request(listener, req, client, addr)
  File "/usr/local/lib/python2.7/dist-packages/gunicorn/workers/sync.py", line 171, in handle_request
    respiter = self.wsgi(environ, resp.start_response)
  File "/usr/local/lib/python2.7/dist-packages/flask/app.py", line 1836, in __call__
    return self.wsgi_app(environ, start_response)
  File "/usr/local/lib/python2.7/dist-packages/werkzeug/contrib/fixers.py", line 148, in __call__
    return self.app(environ, start_response)
  File "/usr/local/lib/python2.7/dist-packages/flask/app.py", line 1820, in wsgi_app
    response = self.make_response(self.handle_exception(e))
  File "/usr/local/lib/python2.7/dist-packages/flask/app.py", line 1403, in handle_exception
    reraise(exc_type, exc_value, tb)
  File "/usr/local/lib/python2.7/dist-packages/flask/app.py", line 1817, in wsgi_app
    response = self.full_dispatch_request()
  File "/usr/local/lib/python2.7/dist-packages/flask/app.py", line 1477, in full_dispatch_request
    rv = self.handle_user_exception(e)
  File "/usr/local/lib/python2.7/dist-packages/flask/app.py", line 1370, in handle_user_exception
    return self.handle_http_exception(e)
  File "/usr/local/lib/python2.7/dist-packages/flask/app.py", line 1330, in handle_http_exception
    return handler(e)
  File "/home/pi/Feedback_box/FeedBack_Box/FeedBack_Box.py", line 144, in page_not_found
    print(request.url)
UnicodeEncodeError: 'ascii' codec can't encode characters in position 110-111: ordinal not in range(128)
[2015-06-19 11:42:14 +0000] [4363] [ERROR] Error handling request
Traceback (most recent call last):
  File "/usr/local/lib/python2.7/dist-packages/gunicorn/workers/sync.py", line 130, in handle
    self.handle_request(listener, req, client, addr)
  File "/usr/local/lib/python2.7/dist-packages/gunicorn/workers/sync.py", line 171, in handle_request
    respiter = self.wsgi(environ, resp.start_response)
  File "/usr/local/lib/python2.7/dist-packages/flask/app.py", line 1836, in __call__
    return self.wsgi_app(environ, start_response)
  File "/usr/local/lib/python2.7/dist-packages/werkzeug/contrib/fixers.py", line 148, in __call__
    return self.app(environ, start_response)
  File "/usr/local/lib/python2.7/dist-packages/flask/app.py", line 1820, in wsgi_app
    response = self.make_response(self.handle_exception(e))
  File "/usr/local/lib/python2.7/dist-packages/flask/app.py", line 1403, in handle_exception
    reraise(exc_type, exc_value, tb)
  File "/usr/local/lib/python2.7/dist-packages/flask/app.py", line 1817, in wsgi_app
    response = self.full_dispatch_request()
  File "/usr/local/lib/python2.7/dist-packages/flask/app.py", line 1477, in full_dispatch_request
    rv = self.handle_user_exception(e)
  File "/usr/local/lib/python2.7/dist-packages/flask/app.py", line 1370, in handle_user_exception
    return self.handle_http_exception(e)
  File "/usr/local/lib/python2.7/dist-packages/flask/app.py", line 1330, in handle_http_exception
    return handler(e)
  File "/home/pi/Feedback_box/FeedBack_Box/FeedBack_Box.py", line 144, in page_not_found
    print(request.url)
UnicodeEncodeError: 'ascii' codec can't encode character u'\xe9' in position 537: ordinal not in range(128)
[2015-06-19 11:42:14 +0000] [4363] [ERROR] Error handling request
Traceback (most recent call last):
  File "/usr/local/lib/python2.7/dist-packages/gunicorn/workers/sync.py", line 130, in handle
    self.handle_request(listener, req, client, addr)
  File "/usr/local/lib/python2.7/dist-packages/gunicorn/workers/sync.py", line 171, in handle_request
    respiter = self.wsgi(environ, resp.start_response)
  File "/usr/local/lib/python2.7/dist-packages/flask/app.py", line 1836, in __call__
    return self.wsgi_app(environ, start_response)
  File "/usr/local/lib/python2.7/dist-packages/werkzeug/contrib/fixers.py", line 148, in __call__
    return self.app(environ, start_response)
  File "/usr/local/lib/python2.7/dist-packages/flask/app.py", line 1820, in wsgi_app
    response = self.make_response(self.handle_exception(e))
  File "/usr/local/lib/python2.7/dist-packages/flask/app.py", line 1403, in handle_exception
    reraise(exc_type, exc_value, tb)
  File "/usr/local/lib/python2.7/dist-packages/flask/app.py", line 1817, in wsgi_app
    response = self.full_dispatch_request()
  File "/usr/local/lib/python2.7/dist-packages/flask/app.py", line 1477, in full_dispatch_request
    rv = self.handle_user_exception(e)
  File "/usr/local/lib/python2.7/dist-packages/flask/app.py", line 1370, in handle_user_exception
    return self.handle_http_exception(e)
  File "/usr/local/lib/python2.7/dist-packages/flask/app.py", line 1330, in handle_http_exception
    return handler(e)
  File "/home/pi/Feedback_box/FeedBack_Box/FeedBack_Box.py", line 144, in page_not_found
    print(request.url)
UnicodeEncodeError: 'ascii' codec can't encode character u'\xe9' in position 537: ordinal not in range(128)
[2015-06-19 11:42:19 +0000] [4363] [ERROR] Error handling request
Traceback (most recent call last):
  File "/usr/local/lib/python2.7/dist-packages/gunicorn/workers/sync.py", line 130, in handle
    self.handle_request(listener, req, client, addr)
  File "/usr/local/lib/python2.7/dist-packages/gunicorn/workers/sync.py", line 171, in handle_request
    respiter = self.wsgi(environ, resp.start_response)
  File "/usr/local/lib/python2.7/dist-packages/flask/app.py", line 1836, in __call__
    return self.wsgi_app(environ, start_response)
  File "/usr/local/lib/python2.7/dist-packages/werkzeug/contrib/fixers.py", line 148, in __call__
    return self.app(environ, start_response)
  File "/usr/local/lib/python2.7/dist-packages/flask/app.py", line 1820, in wsgi_app
    response = self.make_response(self.handle_exception(e))
  File "/usr/local/lib/python2.7/dist-packages/flask/app.py", line 1403, in handle_exception
    reraise(exc_type, exc_value, tb)
  File "/usr/local/lib/python2.7/dist-packages/flask/app.py", line 1817, in wsgi_app
    response = self.full_dispatch_request()
  File "/usr/local/lib/python2.7/dist-packages/flask/app.py", line 1477, in full_dispatch_request
    rv = self.handle_user_exception(e)
  File "/usr/local/lib/python2.7/dist-packages/flask/app.py", line 1370, in handle_user_exception
    return self.handle_http_exception(e)
  File "/usr/local/lib/python2.7/dist-packages/flask/app.py", line 1330, in handle_http_exception
    return handler(e)
  File "/home/pi/Feedback_box/FeedBack_Box/FeedBack_Box.py", line 144, in page_not_found
    print(request.url)
UnicodeEncodeError: 'ascii' codec can't encode characters in position 110-111: ordinal not in range(128)
[2015-06-19 11:42:19 +0000] [4363] [ERROR] Error handling request
Traceback (most recent call last):
  File "/usr/local/lib/python2.7/dist-packages/gunicorn/workers/sync.py", line 130, in handle
    self.handle_request(listener, req, client, addr)
  File "/usr/local/lib/python2.7/dist-packages/gunicorn/workers/sync.py", line 171, in handle_request
    respiter = self.wsgi(environ, resp.start_response)
  File "/usr/local/lib/python2.7/dist-packages/flask/app.py", line 1836, in __call__
    return self.wsgi_app(environ, start_response)
  File "/usr/local/lib/python2.7/dist-packages/werkzeug/contrib/fixers.py", line 148, in __call__
    return self.app(environ, start_response)
  File "/usr/local/lib/python2.7/dist-packages/flask/app.py", line 1820, in wsgi_app
    response = self.make_response(self.handle_exception(e))
  File "/usr/local/lib/python2.7/dist-packages/flask/app.py", line 1403, in handle_exception
    reraise(exc_type, exc_value, tb)
  File "/usr/local/lib/python2.7/dist-packages/flask/app.py", line 1817, in wsgi_app
    response = self.full_dispatch_request()
  File "/usr/local/lib/python2.7/dist-packages/flask/app.py", line 1477, in full_dispatch_request
    rv = self.handle_user_exception(e)
  File "/usr/local/lib/python2.7/dist-packages/flask/app.py", line 1370, in handle_user_exception
    return self.handle_http_exception(e)
  File "/usr/local/lib/python2.7/dist-packages/flask/app.py", line 1330, in handle_http_exception
    return handler(e)
  File "/home/pi/Feedback_box/FeedBack_Box/FeedBack_Box.py", line 144, in page_not_found
    print(request.url)
UnicodeEncodeError: 'ascii' codec can't encode character u'\xe9' in position 537: ordinal not in range(128)
[2015-06-19 11:42:19 +0000] [4363] [ERROR] Error handling request
Traceback (most recent call last):
  File "/usr/local/lib/python2.7/dist-packages/gunicorn/workers/sync.py", line 130, in handle
    self.handle_request(listener, req, client, addr)
  File "/usr/local/lib/python2.7/dist-packages/gunicorn/workers/sync.py", line 171, in handle_request
    respiter = self.wsgi(environ, resp.start_response)
  File "/usr/local/lib/python2.7/dist-packages/flask/app.py", line 1836, in __call__
    return self.wsgi_app(environ, start_response)
  File "/usr/local/lib/python2.7/dist-packages/werkzeug/contrib/fixers.py", line 148, in __call__
    return self.app(environ, start_response)
  File "/usr/local/lib/python2.7/dist-packages/flask/app.py", line 1820, in wsgi_app
    response = self.make_response(self.handle_exception(e))
  File "/usr/local/lib/python2.7/dist-packages/flask/app.py", line 1403, in handle_exception
    reraise(exc_type, exc_value, tb)
  File "/usr/local/lib/python2.7/dist-packages/flask/app.py", line 1817, in wsgi_app
    response = self.full_dispatch_request()
  File "/usr/local/lib/python2.7/dist-packages/flask/app.py", line 1477, in full_dispatch_request
    rv = self.handle_user_exception(e)
  File "/usr/local/lib/python2.7/dist-packages/flask/app.py", line 1370, in handle_user_exception
    return self.handle_http_exception(e)
  File "/usr/local/lib/python2.7/dist-packages/flask/app.py", line 1330, in handle_http_exception
    return handler(e)
  File "/home/pi/Feedback_box/FeedBack_Box/FeedBack_Box.py", line 144, in page_not_found
    print(request.url)
UnicodeEncodeError: 'ascii' codec can't encode character u'\xe9' in position 537: ordinal not in range(128)
